INFO 2025-02-20 14:27:04,699 autoreload Watching for file changes with StatReloader
WARNING 2025-02-20 14:27:53,548 basehttp "GET /api/profile HTTP/1.0" 401 32
WARNING 2025-02-20 14:28:10,381 basehttp "GET /api/profile HTTP/1.0" 401 32
INFO 2025-02-20 14:28:26,687 basehttp "POST /api/signup HTTP/1.0" 200 0
INFO 2025-02-20 14:32:05,347 autoreload Watching for file changes with StatReloader
WARNING 2025-02-20 14:32:29,938 basehttp "GET /api/profile HTTP/1.0" 401 32
INFO 2025-02-20 14:41:03,741 autoreload Watching for file changes with StatReloader
INFO 2025-02-20 14:50:42,368 autoreload Watching for file changes with StatReloader
INFO 2025-02-23 20:29:40,373 autoreload Watching for file changes with StatReloader
INFO 2025-02-23 20:30:08,919 autoreload Watching for file changes with StatReloader
WARNING 2025-02-23 20:30:20,725 basehttp "GET /api/profile HTTP/1.0" 401 32
INFO 2025-02-23 20:30:41,574 basehttp "POST /api/signup HTTP/1.0" 200 0
INFO 2025-02-23 20:30:53,528 basehttp "POST /api/login HTTP/1.0" 200 0
WARNING 2025-02-23 20:31:03,974 basehttp "GET /api/profile HTTP/1.0" 401 32
INFO 2025-02-23 20:31:32,176 basehttp "POST /api/signup HTTP/1.0" 200 0
INFO 2025-02-23 20:31:44,902 basehttp "POST /api/login HTTP/1.0" 200 0
INFO 2025-02-23 20:32:07,989 basehttp "POST /api/verify-2fa HTTP/1.0" 200 0
INFO 2025-02-23 20:32:08,050 basehttp "GET /api/profile HTTP/1.0" 200 291
INFO 2025-02-23 20:32:08,070 basehttp "GET /api/user_avatar HTTP/1.0" 200 7402
INFO 2025-02-23 20:32:11,216 basehttp "GET /api/profile HTTP/1.0" 200 291
INFO 2025-02-23 20:32:11,230 basehttp "GET /api/user_avatar HTTP/1.0" 200 7402
INFO 2025-02-23 20:32:11,244 basehttp "GET /api/profile HTTP/1.0" 200 291
INFO 2025-02-23 20:32:17,765 basehttp "GET /api/profile HTTP/1.0" 200 291
INFO 2025-02-23 20:32:17,777 basehttp "GET /api/user_avatar HTTP/1.0" 200 7402
INFO 2025-02-23 20:32:27,226 basehttp "GET /api/profile HTTP/1.0" 200 291
INFO 2025-02-23 20:32:27,245 basehttp "GET /api/user_avatar HTTP/1.0" 200 7402
INFO 2025-02-23 20:32:34,346 basehttp "GET /api/profile HTTP/1.0" 200 291
INFO 2025-02-23 20:32:34,357 basehttp "GET /api/user_avatar HTTP/1.0" 200 7402
INFO 2025-02-23 21:33:51,486 autoreload Watching for file changes with StatReloader
WARNING 2025-02-23 21:52:33,861 basehttp "GET /api/profile HTTP/1.0" 401 32
WARNING 2025-02-23 21:53:32,552 basehttp "GET /api/profile HTTP/1.0" 401 32
WARNING 2025-02-23 21:53:46,876 basehttp "GET /api/profile HTTP/1.0" 401 32
INFO 2025-02-23 22:10:09,067 autoreload Watching for file changes with StatReloader
INFO 2025-02-23 23:05:25,738 autoreload Watching for file changes with StatReloader
INFO 2025-02-23 23:26:13,536 autoreload Watching for file changes with StatReloader
INFO 2025-02-23 23:27:26,822 autoreload Watching for file changes with StatReloader
INFO 2025-02-23 23:30:54,208 autoreload Watching for file changes with StatReloader
INFO 2025-02-24 09:58:13,298 autoreload Watching for file changes with StatReloader
INFO 2025-02-25 17:48:04,669 autoreload Watching for file changes with StatReloader
INFO 2025-02-25 18:30:38,388 autoreload Watching for file changes with StatReloader
INFO 2025-02-26 11:25:44,010 autoreload Watching for file changes with StatReloader
WARNING 2025-02-26 11:25:54,036 basehttp "GET /api/profile HTTP/1.0" 401 32
INFO 2025-02-26 11:27:45,622 autoreload Watching for file changes with StatReloader
WARNING 2025-02-26 11:27:58,256 basehttp "GET /api/profile HTTP/1.0" 401 32
INFO 2025-02-27 17:56:29,813 autoreload Watching for file changes with StatReloader
INFO 2025-02-27 17:57:20,715 autoreload Watching for file changes with StatReloader
INFO 2025-02-27 18:27:11,210 autoreload Watching for file changes with StatReloader
INFO 2025-02-27 18:28:22,074 autoreload Watching for file changes with StatReloader
INFO 2025-02-27 18:30:32,194 autoreload Watching for file changes with StatReloader
INFO 2025-02-27 19:32:26,694 autoreload Watching for file changes with StatReloader
INFO 2025-02-27 19:36:16,674 autoreload Watching for file changes with StatReloader
WARNING 2025-02-27 19:36:21,551 basehttp "GET /api/profile HTTP/1.0" 401 32
ERROR 2025-02-27 19:36:35,689 log Internal Server Error: /api/signup
Traceback (most recent call last):
  File "/usr/local/lib/python3.12/site-packages/django/db/backends/utils.py", line 105, in _execute
    return self.cursor.execute(sql, params)
           ^^^^^^^^^^^^^^^^^^^^^^^^^^^^^^^^
psycopg2.errors.UndefinedTable: relation "user_management_customuser" does not exist
LINE 1: SELECT 1 AS "a" FROM "user_management_customuser" WHERE "use...
                             ^


The above exception was the direct cause of the following exception:

Traceback (most recent call last):
  File "/usr/local/lib/python3.12/site-packages/django/core/handlers/exception.py", line 55, in inner
    response = get_response(request)
               ^^^^^^^^^^^^^^^^^^^^^
  File "/usr/local/lib/python3.12/site-packages/django/core/handlers/base.py", line 197, in _get_response
    response = wrapped_callback(request, *callback_args, **callback_kwargs)
               ^^^^^^^^^^^^^^^^^^^^^^^^^^^^^^^^^^^^^^^^^^^^^^^^^^^^^^^^^^^^
  File "/usr/local/lib/python3.12/site-packages/django/views/decorators/csrf.py", line 65, in _view_wrapper
    return view_func(request, *args, **kwargs)
           ^^^^^^^^^^^^^^^^^^^^^^^^^^^^^^^^^^^
  File "/usr/local/lib/python3.12/site-packages/django/views/generic/base.py", line 104, in view
    return self.dispatch(request, *args, **kwargs)
           ^^^^^^^^^^^^^^^^^^^^^^^^^^^^^^^^^^^^^^^
  File "/usr/local/lib/python3.12/site-packages/rest_framework/views.py", line 509, in dispatch
    response = self.handle_exception(exc)
               ^^^^^^^^^^^^^^^^^^^^^^^^^^
  File "/usr/local/lib/python3.12/site-packages/rest_framework/views.py", line 469, in handle_exception
    self.raise_uncaught_exception(exc)
  File "/usr/local/lib/python3.12/site-packages/rest_framework/views.py", line 480, in raise_uncaught_exception
    raise exc
  File "/usr/local/lib/python3.12/site-packages/rest_framework/views.py", line 506, in dispatch
    response = handler(request, *args, **kwargs)
               ^^^^^^^^^^^^^^^^^^^^^^^^^^^^^^^^^
  File "/back/transcendence/user_management/views.py", line 221, in post
    if serializer.is_valid():
       ^^^^^^^^^^^^^^^^^^^^^
  File "/usr/local/lib/python3.12/site-packages/rest_framework/serializers.py", line 223, in is_valid
    self._validated_data = self.run_validation(self.initial_data)
                           ^^^^^^^^^^^^^^^^^^^^^^^^^^^^^^^^^^^^^^
  File "/usr/local/lib/python3.12/site-packages/rest_framework/serializers.py", line 442, in run_validation
    value = self.to_internal_value(data)
            ^^^^^^^^^^^^^^^^^^^^^^^^^^^^
  File "/back/transcendence/user_management/serializers.py", line 41, in to_internal_value
    return super().to_internal_value(data)
           ^^^^^^^^^^^^^^^^^^^^^^^^^^^^^^^
  File "/usr/local/lib/python3.12/site-packages/rest_framework/serializers.py", line 499, in to_internal_value
    validated_value = field.run_validation(primitive_value)
                      ^^^^^^^^^^^^^^^^^^^^^^^^^^^^^^^^^^^^^
  File "/usr/local/lib/python3.12/site-packages/rest_framework/fields.py", line 757, in run_validation
    return super().run_validation(data)
           ^^^^^^^^^^^^^^^^^^^^^^^^^^^^
  File "/usr/local/lib/python3.12/site-packages/rest_framework/fields.py", line 539, in run_validation
    self.run_validators(value)
  File "/usr/local/lib/python3.12/site-packages/rest_framework/fields.py", line 551, in run_validators
    validator(value, self)
  File "/usr/local/lib/python3.12/site-packages/rest_framework/validators.py", line 73, in __call__
    if qs_exists(queryset):
       ^^^^^^^^^^^^^^^^^^^
  File "/usr/local/lib/python3.12/site-packages/rest_framework/validators.py", line 21, in qs_exists
    return queryset.exists()
           ^^^^^^^^^^^^^^^^^
  File "/usr/local/lib/python3.12/site-packages/django/db/models/query.py", line 1288, in exists
    return self.query.has_results(using=self.db)
           ^^^^^^^^^^^^^^^^^^^^^^^^^^^^^^^^^^^^^
  File "/usr/local/lib/python3.12/site-packages/django/db/models/sql/query.py", line 660, in has_results
    return compiler.has_results()
           ^^^^^^^^^^^^^^^^^^^^^^
  File "/usr/local/lib/python3.12/site-packages/django/db/models/sql/compiler.py", line 1542, in has_results
    return bool(self.execute_sql(SINGLE))
                ^^^^^^^^^^^^^^^^^^^^^^^^
  File "/usr/local/lib/python3.12/site-packages/django/db/models/sql/compiler.py", line 1574, in execute_sql
    cursor.execute(sql, params)
  File "/usr/local/lib/python3.12/site-packages/django/db/backends/utils.py", line 122, in execute
    return super().execute(sql, params)
           ^^^^^^^^^^^^^^^^^^^^^^^^^^^^
  File "/usr/local/lib/python3.12/site-packages/django/db/backends/utils.py", line 79, in execute
    return self._execute_with_wrappers(
           ^^^^^^^^^^^^^^^^^^^^^^^^^^^^
  File "/usr/local/lib/python3.12/site-packages/django/db/backends/utils.py", line 92, in _execute_with_wrappers
    return executor(sql, params, many, context)
           ^^^^^^^^^^^^^^^^^^^^^^^^^^^^^^^^^^^^
  File "/usr/local/lib/python3.12/site-packages/django/db/backends/utils.py", line 100, in _execute
    with self.db.wrap_database_errors:
         ^^^^^^^^^^^^^^^^^^^^^^^^^^^^
  File "/usr/local/lib/python3.12/site-packages/django/db/utils.py", line 91, in __exit__
    raise dj_exc_value.with_traceback(traceback) from exc_value
  File "/usr/local/lib/python3.12/site-packages/django/db/backends/utils.py", line 105, in _execute
    return self.cursor.execute(sql, params)
           ^^^^^^^^^^^^^^^^^^^^^^^^^^^^^^^^
django.db.utils.ProgrammingError: relation "user_management_customuser" does not exist
LINE 1: SELECT 1 AS "a" FROM "user_management_customuser" WHERE "use...
                             ^

ERROR 2025-02-27 19:36:35,691 basehttp "POST /api/signup HTTP/1.0" 500 185159
ERROR 2025-02-27 19:36:46,180 log Internal Server Error: /api/signup
Traceback (most recent call last):
  File "/usr/local/lib/python3.12/site-packages/django/db/backends/utils.py", line 105, in _execute
    return self.cursor.execute(sql, params)
           ^^^^^^^^^^^^^^^^^^^^^^^^^^^^^^^^
psycopg2.errors.UndefinedTable: relation "user_management_customuser" does not exist
LINE 1: SELECT 1 AS "a" FROM "user_management_customuser" WHERE "use...
                             ^


The above exception was the direct cause of the following exception:

Traceback (most recent call last):
  File "/usr/local/lib/python3.12/site-packages/django/core/handlers/exception.py", line 55, in inner
    response = get_response(request)
               ^^^^^^^^^^^^^^^^^^^^^
  File "/usr/local/lib/python3.12/site-packages/django/core/handlers/base.py", line 197, in _get_response
    response = wrapped_callback(request, *callback_args, **callback_kwargs)
               ^^^^^^^^^^^^^^^^^^^^^^^^^^^^^^^^^^^^^^^^^^^^^^^^^^^^^^^^^^^^
  File "/usr/local/lib/python3.12/site-packages/django/views/decorators/csrf.py", line 65, in _view_wrapper
    return view_func(request, *args, **kwargs)
           ^^^^^^^^^^^^^^^^^^^^^^^^^^^^^^^^^^^
  File "/usr/local/lib/python3.12/site-packages/django/views/generic/base.py", line 104, in view
    return self.dispatch(request, *args, **kwargs)
           ^^^^^^^^^^^^^^^^^^^^^^^^^^^^^^^^^^^^^^^
  File "/usr/local/lib/python3.12/site-packages/rest_framework/views.py", line 509, in dispatch
    response = self.handle_exception(exc)
               ^^^^^^^^^^^^^^^^^^^^^^^^^^
  File "/usr/local/lib/python3.12/site-packages/rest_framework/views.py", line 469, in handle_exception
    self.raise_uncaught_exception(exc)
  File "/usr/local/lib/python3.12/site-packages/rest_framework/views.py", line 480, in raise_uncaught_exception
    raise exc
  File "/usr/local/lib/python3.12/site-packages/rest_framework/views.py", line 506, in dispatch
    response = handler(request, *args, **kwargs)
               ^^^^^^^^^^^^^^^^^^^^^^^^^^^^^^^^^
  File "/back/transcendence/user_management/views.py", line 221, in post
    if serializer.is_valid():
       ^^^^^^^^^^^^^^^^^^^^^
  File "/usr/local/lib/python3.12/site-packages/rest_framework/serializers.py", line 223, in is_valid
    self._validated_data = self.run_validation(self.initial_data)
                           ^^^^^^^^^^^^^^^^^^^^^^^^^^^^^^^^^^^^^^
  File "/usr/local/lib/python3.12/site-packages/rest_framework/serializers.py", line 442, in run_validation
    value = self.to_internal_value(data)
            ^^^^^^^^^^^^^^^^^^^^^^^^^^^^
  File "/back/transcendence/user_management/serializers.py", line 41, in to_internal_value
    return super().to_internal_value(data)
           ^^^^^^^^^^^^^^^^^^^^^^^^^^^^^^^
  File "/usr/local/lib/python3.12/site-packages/rest_framework/serializers.py", line 499, in to_internal_value
    validated_value = field.run_validation(primitive_value)
                      ^^^^^^^^^^^^^^^^^^^^^^^^^^^^^^^^^^^^^
  File "/usr/local/lib/python3.12/site-packages/rest_framework/fields.py", line 757, in run_validation
    return super().run_validation(data)
           ^^^^^^^^^^^^^^^^^^^^^^^^^^^^
  File "/usr/local/lib/python3.12/site-packages/rest_framework/fields.py", line 539, in run_validation
    self.run_validators(value)
  File "/usr/local/lib/python3.12/site-packages/rest_framework/fields.py", line 551, in run_validators
    validator(value, self)
  File "/usr/local/lib/python3.12/site-packages/rest_framework/validators.py", line 73, in __call__
    if qs_exists(queryset):
       ^^^^^^^^^^^^^^^^^^^
  File "/usr/local/lib/python3.12/site-packages/rest_framework/validators.py", line 21, in qs_exists
    return queryset.exists()
           ^^^^^^^^^^^^^^^^^
  File "/usr/local/lib/python3.12/site-packages/django/db/models/query.py", line 1288, in exists
    return self.query.has_results(using=self.db)
           ^^^^^^^^^^^^^^^^^^^^^^^^^^^^^^^^^^^^^
  File "/usr/local/lib/python3.12/site-packages/django/db/models/sql/query.py", line 660, in has_results
    return compiler.has_results()
           ^^^^^^^^^^^^^^^^^^^^^^
  File "/usr/local/lib/python3.12/site-packages/django/db/models/sql/compiler.py", line 1542, in has_results
    return bool(self.execute_sql(SINGLE))
                ^^^^^^^^^^^^^^^^^^^^^^^^
  File "/usr/local/lib/python3.12/site-packages/django/db/models/sql/compiler.py", line 1574, in execute_sql
    cursor.execute(sql, params)
  File "/usr/local/lib/python3.12/site-packages/django/db/backends/utils.py", line 122, in execute
    return super().execute(sql, params)
           ^^^^^^^^^^^^^^^^^^^^^^^^^^^^
  File "/usr/local/lib/python3.12/site-packages/django/db/backends/utils.py", line 79, in execute
    return self._execute_with_wrappers(
           ^^^^^^^^^^^^^^^^^^^^^^^^^^^^
  File "/usr/local/lib/python3.12/site-packages/django/db/backends/utils.py", line 92, in _execute_with_wrappers
    return executor(sql, params, many, context)
           ^^^^^^^^^^^^^^^^^^^^^^^^^^^^^^^^^^^^
  File "/usr/local/lib/python3.12/site-packages/django/db/backends/utils.py", line 100, in _execute
    with self.db.wrap_database_errors:
         ^^^^^^^^^^^^^^^^^^^^^^^^^^^^
  File "/usr/local/lib/python3.12/site-packages/django/db/utils.py", line 91, in __exit__
    raise dj_exc_value.with_traceback(traceback) from exc_value
  File "/usr/local/lib/python3.12/site-packages/django/db/backends/utils.py", line 105, in _execute
    return self.cursor.execute(sql, params)
           ^^^^^^^^^^^^^^^^^^^^^^^^^^^^^^^^
django.db.utils.ProgrammingError: relation "user_management_customuser" does not exist
LINE 1: SELECT 1 AS "a" FROM "user_management_customuser" WHERE "use...
                             ^

ERROR 2025-02-27 19:36:46,181 basehttp "POST /api/signup HTTP/1.0" 500 185424
INFO 2025-02-27 19:39:54,334 autoreload Watching for file changes with StatReloader
INFO 2025-02-27 19:40:41,861 autoreload Watching for file changes with StatReloader
INFO 2025-02-27 19:41:57,601 autoreload Watching for file changes with StatReloader
INFO 2025-02-27 20:01:40,286 autoreload Watching for file changes with StatReloader
INFO 2025-02-27 20:02:51,593 autoreload Watching for file changes with StatReloader
INFO 2025-02-27 20:04:39,414 autoreload Watching for file changes with StatReloader
INFO 2025-02-27 20:15:38,031 autoreload Watching for file changes with StatReloader
INFO 2025-02-27 20:16:48,824 autoreload Watching for file changes with StatReloader
INFO 2025-02-27 20:19:03,392 autoreload Watching for file changes with StatReloader
INFO 2025-02-27 20:24:01,792 autoreload Watching for file changes with StatReloader
INFO 2025-02-27 20:26:43,315 autoreload Watching for file changes with StatReloader
INFO 2025-02-27 20:31:48,266 autoreload Watching for file changes with StatReloader
INFO 2025-02-27 21:32:58,029 autoreload Watching for file changes with StatReloader
INFO 2025-02-27 21:36:17,764 autoreload Watching for file changes with StatReloader
INFO 2025-02-27 22:33:19,425 autoreload Watching for file changes with StatReloader
WARNING 2025-02-27 22:34:24,528 basehttp "GET /api/profile HTTP/1.0" 401 32
ERROR 2025-02-27 22:34:45,575 log Internal Server Error: /api/signup
Traceback (most recent call last):
  File "/usr/local/lib/python3.12/site-packages/django/db/backends/utils.py", line 105, in _execute
    return self.cursor.execute(sql, params)
           ^^^^^^^^^^^^^^^^^^^^^^^^^^^^^^^^
psycopg2.errors.UndefinedTable: relation "user_management_customuser" does not exist
LINE 1: SELECT 1 AS "a" FROM "user_management_customuser" WHERE "use...
                             ^


The above exception was the direct cause of the following exception:

Traceback (most recent call last):
  File "/usr/local/lib/python3.12/site-packages/django/core/handlers/exception.py", line 55, in inner
    response = get_response(request)
               ^^^^^^^^^^^^^^^^^^^^^
  File "/usr/local/lib/python3.12/site-packages/django/core/handlers/base.py", line 197, in _get_response
    response = wrapped_callback(request, *callback_args, **callback_kwargs)
               ^^^^^^^^^^^^^^^^^^^^^^^^^^^^^^^^^^^^^^^^^^^^^^^^^^^^^^^^^^^^
  File "/usr/local/lib/python3.12/site-packages/django/views/decorators/csrf.py", line 65, in _view_wrapper
    return view_func(request, *args, **kwargs)
           ^^^^^^^^^^^^^^^^^^^^^^^^^^^^^^^^^^^
  File "/usr/local/lib/python3.12/site-packages/django/views/generic/base.py", line 104, in view
    return self.dispatch(request, *args, **kwargs)
           ^^^^^^^^^^^^^^^^^^^^^^^^^^^^^^^^^^^^^^^
  File "/usr/local/lib/python3.12/site-packages/rest_framework/views.py", line 509, in dispatch
    response = self.handle_exception(exc)
               ^^^^^^^^^^^^^^^^^^^^^^^^^^
  File "/usr/local/lib/python3.12/site-packages/rest_framework/views.py", line 469, in handle_exception
    self.raise_uncaught_exception(exc)
  File "/usr/local/lib/python3.12/site-packages/rest_framework/views.py", line 480, in raise_uncaught_exception
    raise exc
  File "/usr/local/lib/python3.12/site-packages/rest_framework/views.py", line 506, in dispatch
    response = handler(request, *args, **kwargs)
               ^^^^^^^^^^^^^^^^^^^^^^^^^^^^^^^^^
  File "/back/transcendence/user_management/views.py", line 221, in post
    if serializer.is_valid():
       ^^^^^^^^^^^^^^^^^^^^^
  File "/usr/local/lib/python3.12/site-packages/rest_framework/serializers.py", line 223, in is_valid
    self._validated_data = self.run_validation(self.initial_data)
                           ^^^^^^^^^^^^^^^^^^^^^^^^^^^^^^^^^^^^^^
  File "/usr/local/lib/python3.12/site-packages/rest_framework/serializers.py", line 442, in run_validation
    value = self.to_internal_value(data)
            ^^^^^^^^^^^^^^^^^^^^^^^^^^^^
  File "/back/transcendence/user_management/serializers.py", line 41, in to_internal_value
    return super().to_internal_value(data)
           ^^^^^^^^^^^^^^^^^^^^^^^^^^^^^^^
  File "/usr/local/lib/python3.12/site-packages/rest_framework/serializers.py", line 499, in to_internal_value
    validated_value = field.run_validation(primitive_value)
                      ^^^^^^^^^^^^^^^^^^^^^^^^^^^^^^^^^^^^^
  File "/usr/local/lib/python3.12/site-packages/rest_framework/fields.py", line 757, in run_validation
    return super().run_validation(data)
           ^^^^^^^^^^^^^^^^^^^^^^^^^^^^
  File "/usr/local/lib/python3.12/site-packages/rest_framework/fields.py", line 539, in run_validation
    self.run_validators(value)
  File "/usr/local/lib/python3.12/site-packages/rest_framework/fields.py", line 551, in run_validators
    validator(value, self)
  File "/usr/local/lib/python3.12/site-packages/rest_framework/validators.py", line 73, in __call__
    if qs_exists(queryset):
       ^^^^^^^^^^^^^^^^^^^
  File "/usr/local/lib/python3.12/site-packages/rest_framework/validators.py", line 21, in qs_exists
    return queryset.exists()
           ^^^^^^^^^^^^^^^^^
  File "/usr/local/lib/python3.12/site-packages/django/db/models/query.py", line 1288, in exists
    return self.query.has_results(using=self.db)
           ^^^^^^^^^^^^^^^^^^^^^^^^^^^^^^^^^^^^^
  File "/usr/local/lib/python3.12/site-packages/django/db/models/sql/query.py", line 660, in has_results
    return compiler.has_results()
           ^^^^^^^^^^^^^^^^^^^^^^
  File "/usr/local/lib/python3.12/site-packages/django/db/models/sql/compiler.py", line 1542, in has_results
    return bool(self.execute_sql(SINGLE))
                ^^^^^^^^^^^^^^^^^^^^^^^^
  File "/usr/local/lib/python3.12/site-packages/django/db/models/sql/compiler.py", line 1574, in execute_sql
    cursor.execute(sql, params)
  File "/usr/local/lib/python3.12/site-packages/django/db/backends/utils.py", line 122, in execute
    return super().execute(sql, params)
           ^^^^^^^^^^^^^^^^^^^^^^^^^^^^
  File "/usr/local/lib/python3.12/site-packages/django/db/backends/utils.py", line 79, in execute
    return self._execute_with_wrappers(
           ^^^^^^^^^^^^^^^^^^^^^^^^^^^^
  File "/usr/local/lib/python3.12/site-packages/django/db/backends/utils.py", line 92, in _execute_with_wrappers
    return executor(sql, params, many, context)
           ^^^^^^^^^^^^^^^^^^^^^^^^^^^^^^^^^^^^
  File "/usr/local/lib/python3.12/site-packages/django/db/backends/utils.py", line 100, in _execute
    with self.db.wrap_database_errors:
         ^^^^^^^^^^^^^^^^^^^^^^^^^^^^
  File "/usr/local/lib/python3.12/site-packages/django/db/utils.py", line 91, in __exit__
    raise dj_exc_value.with_traceback(traceback) from exc_value
  File "/usr/local/lib/python3.12/site-packages/django/db/backends/utils.py", line 105, in _execute
    return self.cursor.execute(sql, params)
           ^^^^^^^^^^^^^^^^^^^^^^^^^^^^^^^^
django.db.utils.ProgrammingError: relation "user_management_customuser" does not exist
LINE 1: SELECT 1 AS "a" FROM "user_management_customuser" WHERE "use...
                             ^

ERROR 2025-02-27 22:34:45,577 basehttp "POST /api/signup HTTP/1.0" 500 185235
ERROR 2025-02-27 22:35:05,656 log Internal Server Error: /api/signup
Traceback (most recent call last):
  File "/usr/local/lib/python3.12/site-packages/django/db/backends/utils.py", line 105, in _execute
    return self.cursor.execute(sql, params)
           ^^^^^^^^^^^^^^^^^^^^^^^^^^^^^^^^
psycopg2.errors.UndefinedTable: relation "user_management_customuser" does not exist
LINE 1: SELECT 1 AS "a" FROM "user_management_customuser" WHERE "use...
                             ^


The above exception was the direct cause of the following exception:

Traceback (most recent call last):
  File "/usr/local/lib/python3.12/site-packages/django/core/handlers/exception.py", line 55, in inner
    response = get_response(request)
               ^^^^^^^^^^^^^^^^^^^^^
  File "/usr/local/lib/python3.12/site-packages/django/core/handlers/base.py", line 197, in _get_response
    response = wrapped_callback(request, *callback_args, **callback_kwargs)
               ^^^^^^^^^^^^^^^^^^^^^^^^^^^^^^^^^^^^^^^^^^^^^^^^^^^^^^^^^^^^
  File "/usr/local/lib/python3.12/site-packages/django/views/decorators/csrf.py", line 65, in _view_wrapper
    return view_func(request, *args, **kwargs)
           ^^^^^^^^^^^^^^^^^^^^^^^^^^^^^^^^^^^
  File "/usr/local/lib/python3.12/site-packages/django/views/generic/base.py", line 104, in view
    return self.dispatch(request, *args, **kwargs)
           ^^^^^^^^^^^^^^^^^^^^^^^^^^^^^^^^^^^^^^^
  File "/usr/local/lib/python3.12/site-packages/rest_framework/views.py", line 509, in dispatch
    response = self.handle_exception(exc)
               ^^^^^^^^^^^^^^^^^^^^^^^^^^
  File "/usr/local/lib/python3.12/site-packages/rest_framework/views.py", line 469, in handle_exception
    self.raise_uncaught_exception(exc)
  File "/usr/local/lib/python3.12/site-packages/rest_framework/views.py", line 480, in raise_uncaught_exception
    raise exc
  File "/usr/local/lib/python3.12/site-packages/rest_framework/views.py", line 506, in dispatch
    response = handler(request, *args, **kwargs)
               ^^^^^^^^^^^^^^^^^^^^^^^^^^^^^^^^^
  File "/back/transcendence/user_management/views.py", line 221, in post
    if serializer.is_valid():
       ^^^^^^^^^^^^^^^^^^^^^
  File "/usr/local/lib/python3.12/site-packages/rest_framework/serializers.py", line 223, in is_valid
    self._validated_data = self.run_validation(self.initial_data)
                           ^^^^^^^^^^^^^^^^^^^^^^^^^^^^^^^^^^^^^^
  File "/usr/local/lib/python3.12/site-packages/rest_framework/serializers.py", line 442, in run_validation
    value = self.to_internal_value(data)
            ^^^^^^^^^^^^^^^^^^^^^^^^^^^^
  File "/back/transcendence/user_management/serializers.py", line 41, in to_internal_value
    return super().to_internal_value(data)
           ^^^^^^^^^^^^^^^^^^^^^^^^^^^^^^^
  File "/usr/local/lib/python3.12/site-packages/rest_framework/serializers.py", line 499, in to_internal_value
    validated_value = field.run_validation(primitive_value)
                      ^^^^^^^^^^^^^^^^^^^^^^^^^^^^^^^^^^^^^
  File "/usr/local/lib/python3.12/site-packages/rest_framework/fields.py", line 757, in run_validation
    return super().run_validation(data)
           ^^^^^^^^^^^^^^^^^^^^^^^^^^^^
  File "/usr/local/lib/python3.12/site-packages/rest_framework/fields.py", line 539, in run_validation
    self.run_validators(value)
  File "/usr/local/lib/python3.12/site-packages/rest_framework/fields.py", line 551, in run_validators
    validator(value, self)
  File "/usr/local/lib/python3.12/site-packages/rest_framework/validators.py", line 73, in __call__
    if qs_exists(queryset):
       ^^^^^^^^^^^^^^^^^^^
  File "/usr/local/lib/python3.12/site-packages/rest_framework/validators.py", line 21, in qs_exists
    return queryset.exists()
           ^^^^^^^^^^^^^^^^^
  File "/usr/local/lib/python3.12/site-packages/django/db/models/query.py", line 1288, in exists
    return self.query.has_results(using=self.db)
           ^^^^^^^^^^^^^^^^^^^^^^^^^^^^^^^^^^^^^
  File "/usr/local/lib/python3.12/site-packages/django/db/models/sql/query.py", line 660, in has_results
    return compiler.has_results()
           ^^^^^^^^^^^^^^^^^^^^^^
  File "/usr/local/lib/python3.12/site-packages/django/db/models/sql/compiler.py", line 1542, in has_results
    return bool(self.execute_sql(SINGLE))
                ^^^^^^^^^^^^^^^^^^^^^^^^
  File "/usr/local/lib/python3.12/site-packages/django/db/models/sql/compiler.py", line 1574, in execute_sql
    cursor.execute(sql, params)
  File "/usr/local/lib/python3.12/site-packages/django/db/backends/utils.py", line 122, in execute
    return super().execute(sql, params)
           ^^^^^^^^^^^^^^^^^^^^^^^^^^^^
  File "/usr/local/lib/python3.12/site-packages/django/db/backends/utils.py", line 79, in execute
    return self._execute_with_wrappers(
           ^^^^^^^^^^^^^^^^^^^^^^^^^^^^
  File "/usr/local/lib/python3.12/site-packages/django/db/backends/utils.py", line 92, in _execute_with_wrappers
    return executor(sql, params, many, context)
           ^^^^^^^^^^^^^^^^^^^^^^^^^^^^^^^^^^^^
  File "/usr/local/lib/python3.12/site-packages/django/db/backends/utils.py", line 100, in _execute
    with self.db.wrap_database_errors:
         ^^^^^^^^^^^^^^^^^^^^^^^^^^^^
  File "/usr/local/lib/python3.12/site-packages/django/db/utils.py", line 91, in __exit__
    raise dj_exc_value.with_traceback(traceback) from exc_value
  File "/usr/local/lib/python3.12/site-packages/django/db/backends/utils.py", line 105, in _execute
    return self.cursor.execute(sql, params)
           ^^^^^^^^^^^^^^^^^^^^^^^^^^^^^^^^
django.db.utils.ProgrammingError: relation "user_management_customuser" does not exist
LINE 1: SELECT 1 AS "a" FROM "user_management_customuser" WHERE "use...
                             ^

ERROR 2025-02-27 22:35:05,658 basehttp "POST /api/signup HTTP/1.0" 500 185500
WARNING 2025-02-27 22:41:37,059 basehttp "GET /api/profile HTTP/1.0" 401 32
ERROR 2025-02-27 22:42:06,497 log Internal Server Error: /api/signup
Traceback (most recent call last):
  File "/usr/local/lib/python3.12/site-packages/django/db/backends/utils.py", line 105, in _execute
    return self.cursor.execute(sql, params)
           ^^^^^^^^^^^^^^^^^^^^^^^^^^^^^^^^
psycopg2.errors.UndefinedTable: relation "user_management_customuser" does not exist
LINE 1: SELECT 1 AS "a" FROM "user_management_customuser" WHERE "use...
                             ^


The above exception was the direct cause of the following exception:

Traceback (most recent call last):
  File "/usr/local/lib/python3.12/site-packages/django/core/handlers/exception.py", line 55, in inner
    response = get_response(request)
               ^^^^^^^^^^^^^^^^^^^^^
  File "/usr/local/lib/python3.12/site-packages/django/core/handlers/base.py", line 197, in _get_response
    response = wrapped_callback(request, *callback_args, **callback_kwargs)
               ^^^^^^^^^^^^^^^^^^^^^^^^^^^^^^^^^^^^^^^^^^^^^^^^^^^^^^^^^^^^
  File "/usr/local/lib/python3.12/site-packages/django/views/decorators/csrf.py", line 65, in _view_wrapper
    return view_func(request, *args, **kwargs)
           ^^^^^^^^^^^^^^^^^^^^^^^^^^^^^^^^^^^
  File "/usr/local/lib/python3.12/site-packages/django/views/generic/base.py", line 104, in view
    return self.dispatch(request, *args, **kwargs)
           ^^^^^^^^^^^^^^^^^^^^^^^^^^^^^^^^^^^^^^^
  File "/usr/local/lib/python3.12/site-packages/rest_framework/views.py", line 509, in dispatch
    response = self.handle_exception(exc)
               ^^^^^^^^^^^^^^^^^^^^^^^^^^
  File "/usr/local/lib/python3.12/site-packages/rest_framework/views.py", line 469, in handle_exception
    self.raise_uncaught_exception(exc)
  File "/usr/local/lib/python3.12/site-packages/rest_framework/views.py", line 480, in raise_uncaught_exception
    raise exc
  File "/usr/local/lib/python3.12/site-packages/rest_framework/views.py", line 506, in dispatch
    response = handler(request, *args, **kwargs)
               ^^^^^^^^^^^^^^^^^^^^^^^^^^^^^^^^^
  File "/back/transcendence/user_management/views.py", line 221, in post
    if serializer.is_valid():
       ^^^^^^^^^^^^^^^^^^^^^
  File "/usr/local/lib/python3.12/site-packages/rest_framework/serializers.py", line 223, in is_valid
    self._validated_data = self.run_validation(self.initial_data)
                           ^^^^^^^^^^^^^^^^^^^^^^^^^^^^^^^^^^^^^^
  File "/usr/local/lib/python3.12/site-packages/rest_framework/serializers.py", line 442, in run_validation
    value = self.to_internal_value(data)
            ^^^^^^^^^^^^^^^^^^^^^^^^^^^^
  File "/back/transcendence/user_management/serializers.py", line 41, in to_internal_value
    return super().to_internal_value(data)
           ^^^^^^^^^^^^^^^^^^^^^^^^^^^^^^^
  File "/usr/local/lib/python3.12/site-packages/rest_framework/serializers.py", line 499, in to_internal_value
    validated_value = field.run_validation(primitive_value)
                      ^^^^^^^^^^^^^^^^^^^^^^^^^^^^^^^^^^^^^
  File "/usr/local/lib/python3.12/site-packages/rest_framework/fields.py", line 757, in run_validation
    return super().run_validation(data)
           ^^^^^^^^^^^^^^^^^^^^^^^^^^^^
  File "/usr/local/lib/python3.12/site-packages/rest_framework/fields.py", line 539, in run_validation
    self.run_validators(value)
  File "/usr/local/lib/python3.12/site-packages/rest_framework/fields.py", line 551, in run_validators
    validator(value, self)
  File "/usr/local/lib/python3.12/site-packages/rest_framework/validators.py", line 73, in __call__
    if qs_exists(queryset):
       ^^^^^^^^^^^^^^^^^^^
  File "/usr/local/lib/python3.12/site-packages/rest_framework/validators.py", line 21, in qs_exists
    return queryset.exists()
           ^^^^^^^^^^^^^^^^^
  File "/usr/local/lib/python3.12/site-packages/django/db/models/query.py", line 1288, in exists
    return self.query.has_results(using=self.db)
           ^^^^^^^^^^^^^^^^^^^^^^^^^^^^^^^^^^^^^
  File "/usr/local/lib/python3.12/site-packages/django/db/models/sql/query.py", line 660, in has_results
    return compiler.has_results()
           ^^^^^^^^^^^^^^^^^^^^^^
  File "/usr/local/lib/python3.12/site-packages/django/db/models/sql/compiler.py", line 1542, in has_results
    return bool(self.execute_sql(SINGLE))
                ^^^^^^^^^^^^^^^^^^^^^^^^
  File "/usr/local/lib/python3.12/site-packages/django/db/models/sql/compiler.py", line 1574, in execute_sql
    cursor.execute(sql, params)
  File "/usr/local/lib/python3.12/site-packages/django/db/backends/utils.py", line 122, in execute
    return super().execute(sql, params)
           ^^^^^^^^^^^^^^^^^^^^^^^^^^^^
  File "/usr/local/lib/python3.12/site-packages/django/db/backends/utils.py", line 79, in execute
    return self._execute_with_wrappers(
           ^^^^^^^^^^^^^^^^^^^^^^^^^^^^
  File "/usr/local/lib/python3.12/site-packages/django/db/backends/utils.py", line 92, in _execute_with_wrappers
    return executor(sql, params, many, context)
           ^^^^^^^^^^^^^^^^^^^^^^^^^^^^^^^^^^^^
  File "/usr/local/lib/python3.12/site-packages/django/db/backends/utils.py", line 100, in _execute
    with self.db.wrap_database_errors:
         ^^^^^^^^^^^^^^^^^^^^^^^^^^^^
  File "/usr/local/lib/python3.12/site-packages/django/db/utils.py", line 91, in __exit__
    raise dj_exc_value.with_traceback(traceback) from exc_value
  File "/usr/local/lib/python3.12/site-packages/django/db/backends/utils.py", line 105, in _execute
    return self.cursor.execute(sql, params)
           ^^^^^^^^^^^^^^^^^^^^^^^^^^^^^^^^
django.db.utils.ProgrammingError: relation "user_management_customuser" does not exist
LINE 1: SELECT 1 AS "a" FROM "user_management_customuser" WHERE "use...
                             ^

ERROR 2025-02-27 22:42:06,500 basehttp "POST /api/signup HTTP/1.0" 500 186166
ERROR 2025-02-27 22:42:17,426 log Internal Server Error: /api/signup
Traceback (most recent call last):
  File "/usr/local/lib/python3.12/site-packages/django/db/backends/utils.py", line 105, in _execute
    return self.cursor.execute(sql, params)
           ^^^^^^^^^^^^^^^^^^^^^^^^^^^^^^^^
psycopg2.errors.UndefinedTable: relation "user_management_customuser" does not exist
LINE 1: SELECT 1 AS "a" FROM "user_management_customuser" WHERE "use...
                             ^


The above exception was the direct cause of the following exception:

Traceback (most recent call last):
  File "/usr/local/lib/python3.12/site-packages/django/core/handlers/exception.py", line 55, in inner
    response = get_response(request)
               ^^^^^^^^^^^^^^^^^^^^^
  File "/usr/local/lib/python3.12/site-packages/django/core/handlers/base.py", line 197, in _get_response
    response = wrapped_callback(request, *callback_args, **callback_kwargs)
               ^^^^^^^^^^^^^^^^^^^^^^^^^^^^^^^^^^^^^^^^^^^^^^^^^^^^^^^^^^^^
  File "/usr/local/lib/python3.12/site-packages/django/views/decorators/csrf.py", line 65, in _view_wrapper
    return view_func(request, *args, **kwargs)
           ^^^^^^^^^^^^^^^^^^^^^^^^^^^^^^^^^^^
  File "/usr/local/lib/python3.12/site-packages/django/views/generic/base.py", line 104, in view
    return self.dispatch(request, *args, **kwargs)
           ^^^^^^^^^^^^^^^^^^^^^^^^^^^^^^^^^^^^^^^
  File "/usr/local/lib/python3.12/site-packages/rest_framework/views.py", line 509, in dispatch
    response = self.handle_exception(exc)
               ^^^^^^^^^^^^^^^^^^^^^^^^^^
  File "/usr/local/lib/python3.12/site-packages/rest_framework/views.py", line 469, in handle_exception
    self.raise_uncaught_exception(exc)
  File "/usr/local/lib/python3.12/site-packages/rest_framework/views.py", line 480, in raise_uncaught_exception
    raise exc
  File "/usr/local/lib/python3.12/site-packages/rest_framework/views.py", line 506, in dispatch
    response = handler(request, *args, **kwargs)
               ^^^^^^^^^^^^^^^^^^^^^^^^^^^^^^^^^
  File "/back/transcendence/user_management/views.py", line 221, in post
    if serializer.is_valid():
       ^^^^^^^^^^^^^^^^^^^^^
  File "/usr/local/lib/python3.12/site-packages/rest_framework/serializers.py", line 223, in is_valid
    self._validated_data = self.run_validation(self.initial_data)
                           ^^^^^^^^^^^^^^^^^^^^^^^^^^^^^^^^^^^^^^
  File "/usr/local/lib/python3.12/site-packages/rest_framework/serializers.py", line 442, in run_validation
    value = self.to_internal_value(data)
            ^^^^^^^^^^^^^^^^^^^^^^^^^^^^
  File "/back/transcendence/user_management/serializers.py", line 41, in to_internal_value
    return super().to_internal_value(data)
           ^^^^^^^^^^^^^^^^^^^^^^^^^^^^^^^
  File "/usr/local/lib/python3.12/site-packages/rest_framework/serializers.py", line 499, in to_internal_value
    validated_value = field.run_validation(primitive_value)
                      ^^^^^^^^^^^^^^^^^^^^^^^^^^^^^^^^^^^^^
  File "/usr/local/lib/python3.12/site-packages/rest_framework/fields.py", line 757, in run_validation
    return super().run_validation(data)
           ^^^^^^^^^^^^^^^^^^^^^^^^^^^^
  File "/usr/local/lib/python3.12/site-packages/rest_framework/fields.py", line 539, in run_validation
    self.run_validators(value)
  File "/usr/local/lib/python3.12/site-packages/rest_framework/fields.py", line 551, in run_validators
    validator(value, self)
  File "/usr/local/lib/python3.12/site-packages/rest_framework/validators.py", line 73, in __call__
    if qs_exists(queryset):
       ^^^^^^^^^^^^^^^^^^^
  File "/usr/local/lib/python3.12/site-packages/rest_framework/validators.py", line 21, in qs_exists
    return queryset.exists()
           ^^^^^^^^^^^^^^^^^
  File "/usr/local/lib/python3.12/site-packages/django/db/models/query.py", line 1288, in exists
    return self.query.has_results(using=self.db)
           ^^^^^^^^^^^^^^^^^^^^^^^^^^^^^^^^^^^^^
  File "/usr/local/lib/python3.12/site-packages/django/db/models/sql/query.py", line 660, in has_results
    return compiler.has_results()
           ^^^^^^^^^^^^^^^^^^^^^^
  File "/usr/local/lib/python3.12/site-packages/django/db/models/sql/compiler.py", line 1542, in has_results
    return bool(self.execute_sql(SINGLE))
                ^^^^^^^^^^^^^^^^^^^^^^^^
  File "/usr/local/lib/python3.12/site-packages/django/db/models/sql/compiler.py", line 1574, in execute_sql
    cursor.execute(sql, params)
  File "/usr/local/lib/python3.12/site-packages/django/db/backends/utils.py", line 122, in execute
    return super().execute(sql, params)
           ^^^^^^^^^^^^^^^^^^^^^^^^^^^^
  File "/usr/local/lib/python3.12/site-packages/django/db/backends/utils.py", line 79, in execute
    return self._execute_with_wrappers(
           ^^^^^^^^^^^^^^^^^^^^^^^^^^^^
  File "/usr/local/lib/python3.12/site-packages/django/db/backends/utils.py", line 92, in _execute_with_wrappers
    return executor(sql, params, many, context)
           ^^^^^^^^^^^^^^^^^^^^^^^^^^^^^^^^^^^^
  File "/usr/local/lib/python3.12/site-packages/django/db/backends/utils.py", line 100, in _execute
    with self.db.wrap_database_errors:
         ^^^^^^^^^^^^^^^^^^^^^^^^^^^^
  File "/usr/local/lib/python3.12/site-packages/django/db/utils.py", line 91, in __exit__
    raise dj_exc_value.with_traceback(traceback) from exc_value
  File "/usr/local/lib/python3.12/site-packages/django/db/backends/utils.py", line 105, in _execute
    return self.cursor.execute(sql, params)
           ^^^^^^^^^^^^^^^^^^^^^^^^^^^^^^^^
django.db.utils.ProgrammingError: relation "user_management_customuser" does not exist
LINE 1: SELECT 1 AS "a" FROM "user_management_customuser" WHERE "use...
                             ^

ERROR 2025-02-27 22:42:17,428 basehttp "POST /api/signup HTTP/1.0" 500 186431
INFO 2025-02-27 22:46:37,947 autoreload Watching for file changes with StatReloader
